<?xml version="1.0" encoding="utf-8"?>
<!-- This URDF was automatically created by SolidWorks to URDF Exporter! Originally created by Stephen Brawner (brawner@gmail.com) 
     Commit Version: 1.6.0-4-g7f85cfe  Build Version: 1.6.7995.38578
     For more information, please see http://wiki.ros.org/sw_urdf_exporter -->
<robot
  name="assem2_description">

  <link name="base_footprint"/>
  <link
    name="base_link">
    <inertial>
      <origin
        xyz="0.0656386712520219 -0.0432467828307973 0.0100521759712125"
        rpy="0 0 0" />
      <mass
        value="0.259120162249515" />
      <inertia
        ixx="0.000288711035480735"
        ixy="-5.42298696694902E-07"
        ixz="-1.033172642498E-05"
        iyy="0.00040872876302531"
        iyz="3.84708184328528E-06"
        izz="0.00015929450417956" />
    </inertial>
    <visual>
      <origin
        xyz="0 0 0"
        rpy="0 0 0" />
      <geometry>
        <mesh
          filename="package://assem2_description/meshes/base_link.STL" />
      </geometry>
      <material
        name="">
        <color
          rgba="0.792156862745098 0.819607843137255 0.933333333333333 1" />
      </material>
    </visual>
    <collision>
      <origin
        xyz="0 0 0"
        rpy="0 0 0" />
      <geometry>
        <mesh
          filename="package://assem2_description/meshes/base_link.STL" />
      </geometry>
    </collision>
  </link>

  <joint name="base_joint" type="fixed">
    <parent link="base_footprint"/>
    <child link="base_link"/>
    <origin xyz="0 0 0" rpy="0 0 0"/>
  </joint>

  <!-- Step 1: Dummy link -->
  <link name="hand_synergy_link"/>

  <!-- Step 2: Fixed joint to attach it to the base -->
  <joint name="hand_synergy_fixed" type="fixed">
    <parent link="base_link"/>
    <child link="hand_synergy_link"/>
    <origin xyz="0 0 0" rpy="0 0 0"/>
  </joint>

  <link name="hand_synergy_rotated"/>

  <joint name="hand_synergy" type="revolute">
    <parent link="hand_synergy_link"/>
    <child link="hand_synergy_rotated"/>
    <axis xyz="0 0 1"/>
    <limit lower="0.0" upper="1.0" effort="1" velocity="1"/>
  </joint>


  <link
    name="thumb1_Link">
    <inertial>
      <origin
        xyz="0.00512390130538683 0.0149785760029524 -0.000898769028056828"
        rpy="0 0 0" />
      <mass
        value="0.00782969555542092" />
      <inertia
        ixx="6.23290345863103E-07"
        ixy="-2.27653828063278E-11"
        ixz="-6.40433079706808E-12"
        iyy="3.8516036552849E-07"
        iyz="-7.78149137213318E-09"
        izz="7.69498615659275E-07" />
    </inertial>
    <visual>
      <origin
        xyz="0 0 0"
        rpy="0 0 0" />
      <geometry>
        <mesh
          filename="package://assem2_description/meshes/thumb1_Link.STL" />
      </geometry>
      <material
        name="">
        <color
          rgba="0.792156862745098 0.819607843137255 0.933333333333333 1" />
      </material>
    </visual>
    <collision>
      <origin
        xyz="0 0 0"
        rpy="0 0 0" />
      <geometry>
        <mesh
          filename="package://assem2_description/meshes/thumb1_Link.STL" />
      </geometry>
    </collision>
  </link>
  <joint
    name="thumb_j1"
    type="revolute">
    <origin
      xyz="0.0240518483089937 -0.0462528306122306 -0.0172471775497014"
      rpy="1.33873613613483 -0.948932451668994 -0.000258786914443362" />
    <parent
      link="base_link" />
    <child
      link="thumb1_Link" />
    <axis
      xyz="-1 0 0" />
      
    <!--<mimic joint="hand_synergy" multiplier="-1.2"/>> -->

    <limit
      lower="-1.4"
      upper="-0.2"
      effort="5"
      velocity="0.2" />
  </joint>
  <link
    name="thumb2_Link">
    <inertial>
      <origin
        xyz="0.00512389905179179 0.0163538150272155 -0.000369459809588565"
        rpy="0 0 0" />
      <mass
        value="0.00610021895486931" />
      <inertia
        ixx="5.65725285566143E-07"
        ixy="2.64269415324105E-12"
        ixz="6.00375420712271E-12"
        iyy="2.16034510916205E-07"
        iyz="-2.18166882934033E-08"
        izz="6.72756524738135E-07" />
    </inertial>
    <visual>
      <origin
        xyz="0 0 0"
        rpy="0 0 0" />
      <geometry>
        <mesh
          filename="package://assem2_description/meshes/thumb2_Link.STL" />
      </geometry>
      <material
        name="">
        <color
          rgba="0.792156862745098 0.819607843137255 0.933333333333333 1" />
      </material>
    </visual>
    <collision>
      <origin
        xyz="0 0 0"
        rpy="0 0 0" />
      <geometry>
        <mesh
          filename="package://assem2_description/meshes/thumb2_Link.STL" />
      </geometry>
    </collision>
  </link>
  <joint
    name="thumb_j2"
    type="revolute">
    <origin
      xyz="0 0.031 0"
      rpy="0.318147664815992 0 0" />
    <parent
      link="thumb1_Link" />
    <child
      link="thumb2_Link" />
    <axis
      xyz="-1 0 0" />

    <mimic joint="thumb_j1" multiplier="1.1"/>

    <limit
      lower="-1.2876"
      upper="0.28324"
      effort="4"
      velocity="0.2" />
  </joint>
  <link
    name="r11_Link">
    <inertial>
      <origin
        xyz="0.0106126461268541 0.0138574623397819 -0.000692499995342252"
        rpy="0 0 0" />
      <mass
        value="0.00505163456925077" />
      <inertia
        ixx="3.45504087921045E-07"
        ixy="-1.7648803979526E-11"
        ixz="1.15021663613417E-11"
        iyy="1.6934687929108E-07"
        iyz="-4.26690958776279E-09"
        izz="4.09666083226781E-07" />
    </inertial>
    <visual>
      <origin
        xyz="0 0 0"
        rpy="0 0 0" />
      <geometry>
        <mesh
          filename="package://assem2_description/meshes/r11_Link.STL" />
      </geometry>
      <material
        name="">
        <color
          rgba="0.792156862745098 0.819607843137255 0.933333333333333 1" />
      </material>
    </visual>
    <collision>
      <origin
        xyz="0 0 0"
        rpy="0 0 0" />
      <geometry>
        <mesh
          filename="package://assem2_description/meshes/r11_Link.STL" />
      </geometry>
    </collision>
  </link>
  <joint
    name="r1_j1"
    type="revolute">
    <origin
      xyz="0.021540766547458 -0.0462886971045631 0.0651169842968732"
      rpy="1.65806278939658 0 0" />
    <parent
      link="base_link" />
    <child
      link="r11_Link" />
    <axis
      xyz="1 0 0" />

    <mimic joint="hand_synergy" multiplier="1.2"/>

    <limit
      lower="0"
      upper="1.4835"
      effort="4"
      velocity="0.2" />
  </joint>
  <link
    name="r12_Link">
    <inertial>
      <origin
        xyz="0.00948526334559017 0.011319051574415 -0.000637443423010794"
        rpy="0 0 0" />
      <mass
        value="0.00316423445901308" />
      <inertia
        ixx="1.52922072642436E-07"
        ixy="-2.95022509642198E-12"
        ixz="-3.98120081602575E-12"
        iyy="8.21074183350032E-08"
        iyz="-2.05574054430349E-09"
        izz="1.87613484946731E-07" />
    </inertial>
    <visual>
      <origin
        xyz="0 0 0"
        rpy="0 0 0" />
      <geometry>
        <mesh
          filename="package://assem2_description/meshes/r12_Link.STL" />
      </geometry>
      <material
        name="">
        <color
          rgba="0.792156862745098 0.819607843137255 0.933333333333333 1" />
      </material>
    </visual>
    <collision>
      <origin
        xyz="0 0 0"
        rpy="0 0 0" />
      <geometry>
        <mesh
          filename="package://assem2_description/meshes/r12_Link.STL" />
      </geometry>
    </collision>
  </link>
  <joint
    name="r1_j2"
    type="revolute">
    <origin
      xyz="0.00112607587808405 0.029 0"
      rpy="0.0349065850414309 0 0" />
    <parent
      link="r11_Link" />
    <child
      link="r12_Link" />
    <axis
      xyz="1 0 0" />

    <mimic joint="r1_j1" multiplier="1.0"/>

    <limit
      lower="0"
      upper="1.5708"
      effort="5"
      velocity="0.2" />
  </joint>
  <link
    name="r13_Link">
    <inertial>
      <origin
        xyz="0.0083883098520136 0.0138316339526323 -0.000305335243949517"
        rpy="0 0 0" />
      <mass
        value="0.00295264403592367" />
      <inertia
        ixx="2.10142945758861E-07"
        ixy="-3.99673727223903E-13"
        ixz="-7.77469702902124E-13"
        iyy="5.61707534590071E-08"
        iyz="-6.02567806578341E-09"
        izz="2.35429968122707E-07" />
    </inertial>
    <visual>
      <origin
        xyz="0 0 0"
        rpy="0 0 0" />
      <geometry>
        <mesh
          filename="package://assem2_description/meshes/r13_Link.STL" />
      </geometry>
      <material
        name="">
        <color
          rgba="0.792156862745098 0.819607843137255 0.933333333333333 1" />
      </material>
    </visual>
    <collision>
      <origin
        xyz="0 0 0"
        rpy="0 0 0" />
      <geometry>
        <mesh
          filename="package://assem2_description/meshes/r13_Link.STL" />
      </geometry>
    </collision>
  </link>
  <joint
    name="r1_j3"
    type="revolute">
    <origin
      xyz="0.0010967437272964 0.024 0"
      rpy="0.034906585038563 0 0" />
    <parent
      link="r12_Link" />
    <child
      link="r13_Link" />
    <axis
      xyz="-1 0 0" />

    <mimic joint="r1_j1" multiplier="-0.8"/>

    <limit
      lower="-1.0472"
      upper="0"
      effort="4"
      velocity="0.2" />
  </joint>
  <link
    name="middle1_Link">
    <inertial>
      <origin
        xyz="0.0109180043393285 0.0148232616995928 -0.000651883383610372"
        rpy="0 0 0" />
      <mass
        value="0.00545833962203947" />
      <inertia
        ixx="4.20728383042533E-07"
        ixy="-1.09435181644222E-11"
        ixz="-1.02902378312803E-12"
        iyy="1.83607706583251E-07"
        iyz="-4.83669878207309E-09"
        izz="4.89363446589277E-07" />
    </inertial>
    <visual>
      <origin
        xyz="0 0 0"
        rpy="0 0 0" />
      <geometry>
        <mesh
          filename="package://assem2_description/meshes/middle1_Link.STL" />
      </geometry>
      <material
        name="">
        <color
          rgba="0.792156862745098 0.819607843137255 0.933333333333333 1" />
      </material>
    </visual>
    <collision>
      <origin
        xyz="0 0 0"
        rpy="0 0 0" />
      <geometry>
        <mesh
          filename="package://assem2_description/meshes/middle1_Link.STL" />
      </geometry>
    </collision>
  </link>
  <joint
    name="middle_j1"
    type="revolute">
    <origin
      xyz="0.0440176635890045 -0.0460986682470855 0.066692131425617"
      rpy="1.59876267557947 0.0174497310570342 -0.0202042158612193" />
    <parent
      link="base_link" />
    <child
      link="middle1_Link" />
    <axis
      xyz="1 0 0" />

    <mimic joint="hand_synergy" multiplier="1.3"/>

    <limit
      lower="-0.034784"
      upper="1.536"
      effort="4"
      velocity="0.2" />
  </joint>
  <link
    name="middle2_Link">
    <inertial>
      <origin
        xyz="0.00975020937049818 0.0122814878785258 -0.000595623262741193"
        rpy="0 0 0" />
      <mass
        value="0.00347421007174819" />
      <inertia
        ixx="1.92893028184273E-07"
        ixy="-2.88853610777076E-12"
        ixz="-3.35455479364462E-12"
        iyy="9.05970098325026E-08"
        iyz="-2.41855667765878E-09"
        izz="2.3068124017024E-07" />
    </inertial>
    <visual>
      <origin
        xyz="0 0 0"
        rpy="0 0 0" />
      <geometry>
        <mesh
          filename="package://assem2_description/meshes/middle2_Link.STL" />
      </geometry>
      <material
        name="">
        <color
          rgba="0.792156862745098 0.819607843137255 0.933333333333333 1" />
      </material>
    </visual>
    <collision>
      <origin
        xyz="0 0 0"
        rpy="0 0 0" />
      <geometry>
        <mesh
          filename="package://assem2_description/meshes/middle2_Link.STL" />
      </geometry>
    </collision>
  </link>
  <joint
    name="middle_j2"
    type="revolute">
    <origin
      xyz="0.00116795153597407 0.031 0"
      rpy="0.0349065850383234 0 0" />
    <parent
      link="middle1_Link" />
    <child
      link="middle2_Link" />
    <axis
      xyz="-1 0 0" />

    <mimic joint="middle_j1" multiplier="-1.0"/>

    <limit
      lower="-1.5708"
      upper="0"
      effort="4"
      velocity="0.2" />
  </joint>
  <link
    name="middle3_Link">
    <inertial>
      <origin
        xyz="0.00861075553653146 0.0147804782644377 -0.000296908093710115"
        rpy="0 0 0" />
      <mass
        value="0.00317733360346207" />
      <inertia
        ixx="2.55769356163239E-07"
        ixy="1.11906784018037E-12"
        ixz="9.69949322385877E-14"
        iyy="6.08014811267132E-08"
        iyz="-6.57411733131653E-09"
        izz="2.83052492523849E-07" />
    </inertial>
    <visual>
      <origin
        xyz="0 0 0"
        rpy="0 0 0" />
      <geometry>
        <mesh
          filename="package://assem2_description/meshes/middle3_Link.STL" />
      </geometry>
      <material
        name="">
        <color
          rgba="0.792156862745098 0.819607843137255 0.933333333333333 1" />
      </material>
    </visual>
    <collision>
      <origin
        xyz="0 0 0"
        rpy="0 0 0" />
      <geometry>
        <mesh
          filename="package://assem2_description/meshes/middle3_Link.STL" />
      </geometry>
    </collision>
  </link>
  <joint
    name="middle_j3"
    type="revolute">
    <origin
      xyz="0.00113938236336966 0.0260000000000002 0"
      rpy="0.104719755119606 0 0" />
    <parent
      link="middle2_Link" />
    <child
      link="middle3_Link" />
    <axis
      xyz="-1 0 0" />
    
    <mimic joint="middle_j1" multiplier="-0.7"/>

    <limit
      lower="-0.99484"
      upper="0"
      effort="4"
      velocity="0.2" />
  </joint>
  <link
    name="r21_Link">
    <inertial>
      <origin
        xyz="0.0112017617861178 0.0138574615965664 -0.000692455340707394"
        rpy="0 0 0" />
      <mass
        value="0.00505162053540393" />
      <inertia
        ixx="3.45503717620925E-07"
        ixy="-1.75283568065723E-11"
        ixz="1.02027944508691E-11"
        iyy="1.6934653608407E-07"
        iyz="-4.26735340598669E-09"
        izz="4.09663829555223E-07" />
    </inertial>
    <visual>
      <origin
        xyz="0 0 0"
        rpy="0 0 0" />
      <geometry>
        <mesh
          filename="package://assem2_description/meshes/r21_Link.STL" />
      </geometry>
      <material
        name="">
        <color
          rgba="0.792156862745098 0.819607843137255 0.933333333333333 1" />
      </material>
    </visual>
    <collision>
      <origin
        xyz="0 0 0"
        rpy="0 0 0" />
      <geometry>
        <mesh
          filename="package://assem2_description/meshes/r21_Link.STL" />
      </geometry>
    </collision>
  </link>
  <joint
    name="r2_j1"
    type="revolute">
    <origin
      xyz="0.0669125531917285 -0.0465454519734037 0.0663061932721765"
      rpy="1.59891291317393 -0.0174497310570365 0.02020421586122" />
    <parent
      link="base_link" />
    <child
      link="r21_Link" />
    <axis
      xyz="-1 0 0" />
    
    <mimic joint="hand_synergy" multiplier="-1.3"/>

    <limit
      lower="-1.5708"
      upper="0"
      effort="4"
      velocity="0.2" />
  </joint>
  <link
    name="r22_Link">
    <inertial>
      <origin
        xyz="0.00998652762818737 0.0113190599232044 -0.000637422699429603"
        rpy="0 0 0" />
      <mass
        value="0.00316424983547656" />
      <inertia
        ixx="1.52922210556909E-07"
        ixy="-2.82714325934718E-12"
        ixz="-4.36721266205461E-12"
        iyy="8.21081713555794E-08"
        iyz="-2.05574740931456E-09"
        izz="1.87614766096003E-07" />
    </inertial>
    <visual>
      <origin
        xyz="0 0 0"
        rpy="0 0 0" />
      <geometry>
        <mesh
          filename="package://assem2_description/meshes/r22_Link.STL" />
      </geometry>
      <material
        name="">
        <color
          rgba="0.792156862745098 0.819607843137255 0.933333333333333 1" />
      </material>
    </visual>
    <collision>
      <origin
        xyz="0 0 0"
        rpy="0 0 0" />
      <geometry>
        <mesh
          filename="package://assem2_description/meshes/r22_Link.STL" />
      </geometry>
    </collision>
  </link>
  <joint
    name="r2_j2"
    type="revolute">
    <origin
      xyz="0.00121393188528138 0.0289999999999993 0"
      rpy="0.0086607304006959 0 0" />
    <parent
      link="r21_Link" />
    <child
      link="r22_Link" />
    <axis
      xyz="1 0 0" />

    <mimic joint="r2_j1" multiplier="-1.0"/>

    <limit
      lower="-0.043567"
      upper="1.5621"
      effort="4"
      velocity="0.2" />
  </joint>
  <link
    name="r23_Link">
    <inertial>
      <origin
        xyz="0.00893033084632912 0.0138316331340014 -0.000305281262344845"
        rpy="0 0 0" />
      <mass
        value="0.00295275229934227" />
      <inertia
        ixx="2.10143973929486E-07"
        ixy="-7.23031705140317E-13"
        ixz="-2.17508601173165E-12"
        iyy="5.61754366145757E-08"
        iyz="-6.02579151232286E-09"
        izz="2.35436656971005E-07" />
    </inertial>
    <visual>
      <origin
        xyz="0 0 0"
        rpy="0 0 0" />
      <geometry>
        <mesh
          filename="package://assem2_description/meshes/r23_Link.STL" />
      </geometry>
      <material
        name="">
        <color
          rgba="0.792156862745098 0.819607843137255 0.933333333333333 1" />
      </material>
    </visual>
    <collision>
      <origin
        xyz="0 0 0"
        rpy="0 0 0" />
      <geometry>
        <mesh
          filename="package://assem2_description/meshes/r23_Link.STL" />
      </geometry>
    </collision>
  </link>
  <joint
    name="r2_j3"
    type="revolute">
    <origin
      xyz="0.00105627715725304 0.024 0"
      rpy="0.0349065850398856 0 0" />
    <parent
      link="r22_Link" />
    <child
      link="r23_Link" />
    <axis
      xyz="-1 0 0" />
    
    <mimic joint="r2_j1" multiplier="0.7"/>

    <limit
      lower="-1.5708"
      upper="0"
      effort="4"
      velocity="0.2" />
  </joint>
  <link
    name="pinky1_Link">
    <inertial>
      <origin
        xyz="0.0100814045770639 0.0132424873934518 -0.000560391542164668"
        rpy="0 0 0" />
      <mass
        value="0.00378439613099857" />
      <inertia
        ixx="2.39762405025283E-07"
        ixy="-3.00053564557227E-12"
        ixz="-4.98740081394117E-12"
        iyy="9.90876367051699E-08"
        iyz="-2.78446123969546E-09"
        izz="2.80666197332003E-07" />
    </inertial>
    <visual>
      <origin
        xyz="0 0 0"
        rpy="0 0 0" />
      <geometry>
        <mesh
          filename="package://assem2_description/meshes/pinky1_Link.STL" />
      </geometry>
      <material
        name="">
        <color
          rgba="0.792156862745098 0.819607843137255 0.933333333333333 1" />
      </material>
    </visual>
    <collision>
      <origin
        xyz="0 0 0"
        rpy="0 0 0" />
      <geometry>
        <mesh
          filename="package://assem2_description/meshes/pinky1_Link.STL" />
      </geometry>
    </collision>
  </link>
  <joint
    name="pinky_j1"
    type="revolute">
    <origin
      xyz="0.0909862690963969 -0.0460068210277935 0.0617178593201947"
      rpy="1.5602882514778 -0.0174511735876714 0.015584157838284" />
    <parent
      link="base_link" />
    <child
      link="pinky1_Link" />
    <axis
      xyz="-1 0 0" />
    
    <mimic joint="hand_synergy" multiplier="-1.15"/>

    <limit
      lower="-1.5522"
      upper="0.018643"
      effort="4"
      velocity="0.2" />
  </joint>
  <link
    name="pinky2_Link">
    <inertial>
      <origin
        xyz="0.00888126411418376 0.010663021989836 -0.000488394100891118"
        rpy="0 0 0" />
      <mass
        value="0.00226842276697224" />
      <inertia
        ixx="1.0144868442032E-07"
        ixy="-5.5733944423488E-13"
        ixz="-6.39143230088185E-13"
        iyy="4.45533391970744E-08"
        iyz="-1.19705101290774E-09"
        izz="1.22087606613138E-07" />
    </inertial>
    <visual>
      <origin
        xyz="0 0 0"
        rpy="0 0 0" />
      <geometry>
        <mesh
          filename="package://assem2_description/meshes/pinky2_Link.STL" />
      </geometry>
      <material
        name="">
        <color
          rgba="0.792156862745098 0.819607843137255 0.933333333333333 1" />
      </material>
    </visual>
    <collision>
      <origin
        xyz="0 0 0"
        rpy="0 0 0" />
      <geometry>
        <mesh
          filename="package://assem2_description/meshes/pinky2_Link.STL" />
      </geometry>
    </collision>
  </link>
  <joint
    name="pinky_j2"
    type="revolute">
    <origin
      xyz="0.00120000271622225 0.028 0"
      rpy="0.0349065850403582 0 0" />
    <parent
      link="pinky1_Link" />
    <child
      link="pinky2_Link" />
    <axis
      xyz="-1 0 0" />
    <mimic joint="pinky_j1" multiplier="1.1"/>

    <limit
      lower="-1.5708"
      upper="0"
      effort="4"
      velocity="0.2" />
  </joint>
  <link
    name="pinky3_Link">
    <inertial>
      <origin
        xyz="0.00795294187668354 0.0125582589042525 -0.000236691271445121"
        rpy="0 0 0" />
      <mass
        value="0.00194016989437313" />
      <inertia
        ixx="1.23532246699094E-07"
        ixy="1.11497589612462E-12"
        ixz="3.40673667833946E-12"
        iyy="2.70942905057707E-08"
        iyz="-2.28860084336207E-09"
        izz="1.37453558046944E-07" />
    </inertial>
    <visual>
      <origin
        xyz="0 0 0"
        rpy="0 0 0" />
      <geometry>
        <mesh
          filename="package://assem2_description/meshes/pinky3_Link.STL" />
      </geometry>
      <material
        name="">
        <color
          rgba="0.792156862745098 0.819607843137255 0.933333333333333 1" />
      </material>
    </visual>
    <collision>
      <origin
        xyz="0 0 0"
        rpy="0 0 0" />
      <geometry>
        <mesh
          filename="package://assem2_description/meshes/pinky3_Link.STL" />
      </geometry>
    </collision>
  </link>
  <joint
    name="pinky_j3"
    type="revolute">
    <origin
      xyz="0.00092831414823398 0.023 0"
      rpy="0.03490658503964 0 0" />
    <parent
      link="pinky2_Link" />
    <child
      link="pinky3_Link" />
    <axis
      xyz="-1 0 0" />
    
    <mimic joint="pinky_j1" multiplier="0.85"/>

    <limit
      lower="-1.0472"
      upper="0"
      effort="4"
      velocity="0.2" />
  </joint>
</robot>